<?xml version="1.0"?>
<!--
  Gazebo ROS ackermann drive plugin demo
  Try sending commands:
    ros2 topic pub /demo/cmd_demo geometry_msgs/msg/Twist '{linear: {x: 1.0}, angular: {z: 0.1}}' -1
  Try listening to odometry:
    ros2 topic echo /demo/odom_demo
  Try listening to odometer reading(linear distance convered):
    ros2 topic echo /demo/distance_demo
  Try listening to TF:
    ros2 run tf2_ros tf2_echo odom_demo chassis
    and other links
-->
<sdf version="1.6">
  <world name="default">
    <include>
      <uri>model://sun</uri>
    </include>

    <include>
      <uri>model://ground_plane</uri>
    </include>

    <model name='racecar'>
        <link name='base_link'>
        <inertial>
            <pose>0.151394 0 0.052361 0 -0 0</pose>
            <mass>4.13003</mass>
            <inertia>
            <ixx>0.0113243</ixx>
            <ixy>0</ixy>
            <ixz>-0.00110794</ixz>
            <iyy>0.0528584</iyy>
            <iyz>0</iyz>
            <izz>0.0603912</izz>
            </inertia>
        </inertial>
        <collision name='base_link_fixed_joint_lump__laser_collision'>
            <pose>0.265 0 0.125 0 -0 0</pose>
            <geometry>
            <box>
                <size>0.1 0.1 0.1</size>
            </box>
            </geometry>
            <surface>
            <contact>
                <ode/>
            </contact>
            <friction>
                <ode/>
            </friction>
            </surface>
        </collision>
        <collision name='base_link_fixed_joint_lump__zed_camera_link_collision_1'>
            <pose>0.39 0 0.09 0 -0 0</pose>
            <geometry>
            <box>
                <size>0.033 0.175 0.03</size>
            </box>
            </geometry>
        </collision>
        <visual name='base_link_fixed_joint_lump__chassis_visual'>
            <pose>0 0 0.05 0 -0 0</pose>
            <geometry>
            <mesh>
                <scale>1 1 1</scale>
                <uri>/root/dd_ws/install/racecar_description/share/racecar_description/meshes/chassis.STL</uri>
            </mesh>
            </geometry>
            <material>
            <script>
                <name>Gazebo/Blue</name>
                <uri>file://media/materials/scripts/gazebo.material</uri>
            </script>
            </material>
        </visual>
        <visual name='base_link_fixed_joint_lump__laser_visual_1'>
            <pose>0.265 0 0.125 0 -0 0</pose>
            <geometry>
            <mesh>
                <scale>1 1 1</scale>
                <uri>/root/dd_ws/install/racecar_description/share/racecar_description/meshes/hokuyo.dae</uri>
            </mesh>
            </geometry>
            <material>
            <script>
                <name>Gazebo/Grey</name>
                <uri>file://media/materials/scripts/gazebo.material</uri>
            </script>
            </material>
        </visual>
        <visual name='base_link_fixed_joint_lump__zed_camera_link_visual_2'>
            <pose>0.39 0 0.09 0 -0 0</pose>
            <geometry>
            <box>
                <size>0.033 0.175 0.03</size>
            </box>
            </geometry>
        </visual>
        <velocity_decay/>
        <velocity_decay/>
        <sensor name='hokuyo_sensor' type='ray'>
            <visualize>1</visualize>
            <update_rate>40</update_rate>
            <ray>
            <scan>
                <horizontal>
                <samples>1081</samples>
                <resolution>1</resolution>
                <min_angle>-2.35619</min_angle>
                <max_angle>2.35619</max_angle>
                </horizontal>
            </scan>
            <range>
                <min>0.1</min>
                <max>10</max>
                <resolution>0.01</resolution>
            </range>
            <noise>
                <mean>0</mean>
                <stddev>0.01</stddev>
                <type>gaussian</type>
            </noise>
            </ray>
            <plugin name='gazebo_ros_head_hokuyo_controller' filename='libgazebo_ros_ray_sensor.so'>
            <topicName>/scan</topicName>
            <frameName>laser</frameName>
            </plugin>
            <pose>0.265 0 0.125 0 -0 0</pose>
        </sensor>
        <gravity>1</gravity>
        <velocity_decay/>
        <sensor name='zed_camera_left_sensor' type='camera'>
            <update_rate>30</update_rate>
            <camera name='zed_camera_left_camera'>
            <horizontal_fov>0.870922</horizontal_fov>
            <image>
                <width>640</width>
                <height>480</height>
                <format>B8G8R8</format>
            </image>
            <clip>
                <near>0.02</near>
                <far>300</far>
            </clip>
            <noise>
                <type>gaussian</type>
                <mean>0</mean>
                <stddev>0.007</stddev>
            </noise>
            </camera>
            <plugin name='camera_controller' filename='libgazebo_ros_camera.so'>
            <alwaysOn>1</alwaysOn>
            <updateRate>30.0</updateRate>
            <cameraName>/camera/zed</cameraName>
            <imageTopicName>rgb/image_rect_color</imageTopicName>
            <cameraInfoTopicName>rgb/camera_info</cameraInfoTopicName>
            <frameName>camera_link</frameName>
            <hackBaseline>0</hackBaseline>
            <distortionK1>0.0</distortionK1>
            <distortionK2>0.0</distortionK2>
            <distortionK3>0.0</distortionK3>
            <distortionT1>0.0</distortionT1>
            <distortionT2>0.0</distortionT2>
            </plugin>
            <pose>0.39 0.06 0.09 0 -0 0</pose>
        </sensor>
        </link>
        <joint name='left_rear_wheel_joint' type='revolute'>
        <pose relative_to='base_link'>0 0.1 0.05 1.5708 -0 0</pose>
        <parent>base_link</parent>
        <child>left_rear_wheel</child>
        <axis>
            <xyz>0 0 -1</xyz>
            <limit>
            <lower>-1e+16</lower>
            <upper>1e+16</upper>
            </limit>
            <dynamics>
            <spring_reference>0</spring_reference>
            <spring_stiffness>0</spring_stiffness>
            </dynamics>
        </axis>
        </joint>
        <link name='left_rear_wheel'>
        <pose relative_to='left_rear_wheel_joint'>0 0 0 0 -0 0</pose>
        <inertial>
            <pose>0 0 -0.0225 0 -0 0</pose>
            <mass>0.34055</mass>
            <inertia>
            <ixx>0.00026046</ixx>
            <ixy>0</ixy>
            <ixz>0</ixz>
            <iyy>0.00026046</iyy>
            <iyz>0</iyz>
            <izz>0.00041226</izz>
            </inertia>
        </inertial>
        <collision name='left_rear_wheel_collision'>
            <pose>0 0 -0.0225 0 -0 0</pose>
            <geometry>
            <cylinder>
                <length>0.045</length>
                <radius>0.05</radius>
            </cylinder>
            </geometry>
            <surface>
            <contact>
                <ode>
                <kp>1e+07</kp>
                <kd>1</kd>
                </ode>
            </contact>
            <friction>
                <ode>
                <mu>1</mu>
                <mu2>1</mu2>
                <fdir1>1 0 0</fdir1>
                </ode>
            </friction>
            </surface>
        </collision>
        <visual name='left_rear_wheel_visual'>
            <pose>0 0 0 0 -0 0</pose>
            <geometry>
            <mesh>
                <scale>1 1 1</scale>
                <uri>/root/dd_ws/install/racecar_description/share/racecar_description/meshes/left_rear_wheel.STL</uri>
            </mesh>
            </geometry>
            <material>
            <script>
                <name>Gazebo/Black</name>
                <uri>file://media/materials/scripts/gazebo.material</uri>
            </script>
            </material>
        </visual>
        <gravity>1</gravity>
        <velocity_decay/>
        </link>
        <joint name='left_steering_hinge_joint' type='revolute'>
        <pose relative_to='base_link'>0.325 0.1 0.05 3.14159 1.57079 3.14159</pose>
        <parent>base_link</parent>
        <child>left_steering_hinge</child>
        <axis>
            <xyz>-1 0 0</xyz>
            <limit>
            <lower>-1</lower>
            <upper>1</upper>
            <effort>10</effort>
            <velocity>100</velocity>
            </limit>
            <dynamics>
            <spring_reference>0</spring_reference>
            <spring_stiffness>0</spring_stiffness>
            </dynamics>
        </axis>
        </joint>
        <link name='left_steering_hinge'>
        <pose relative_to='left_steering_hinge_joint'>0 0 0 0 -0 0</pose>
        <inertial>
            <pose>0 0 0 0 -0 0</pose>
            <mass>0.1</mass>
            <inertia>
            <ixx>4e-06</ixx>
            <ixy>0</ixy>
            <ixz>0</ixz>
            <iyy>4e-06</iyy>
            <iyz>0</iyz>
            <izz>4e-06</izz>
            </inertia>
        </inertial>
        <visual name='left_steering_hinge_visual'>
            <pose>0 0 0 0 -0 0</pose>
            <geometry>
            <mesh>
                <scale>1 1 1</scale>
                <uri>/root/dd_ws/install/racecar_description/share/racecar_description/meshes/left_steering_hinge.STL</uri>
            </mesh>
            </geometry>
        </visual>
        </link>
        <joint name='left_front_wheel_joint' type='revolute'>
        <pose relative_to='left_steering_hinge'>0 0 0 1.5708 -0 0</pose>
        <parent>left_steering_hinge</parent>
        <child>left_front_wheel</child>
        <axis>
            <xyz>0 0 -1</xyz>
            <limit>
            <lower>-1e+16</lower>
            <upper>1e+16</upper>
            </limit>
            <dynamics>
            <spring_reference>0</spring_reference>
            <spring_stiffness>0</spring_stiffness>
            </dynamics>
        </axis>
        </joint>
        <link name='left_front_wheel'>
        <pose relative_to='left_front_wheel_joint'>0 0 0 0 -0 0</pose>
        <inertial>
            <pose>0 0 -0.0225 0 -0 0</pose>
            <mass>0.34055</mass>
            <inertia>
            <ixx>0.00026046</ixx>
            <ixy>0</ixy>
            <ixz>0</ixz>
            <iyy>0.00026046</iyy>
            <iyz>0</iyz>
            <izz>0.00041226</izz>
            </inertia>
        </inertial>
        <collision name='left_front_wheel_collision'>
            <pose>0 0 -0.0225 0 -0 0</pose>
            <geometry>
            <cylinder>
                <length>0.045</length>
                <radius>0.05</radius>
            </cylinder>
            </geometry>
            <surface>
            <contact>
                <ode>
                <kp>1e+07</kp>
                <kd>1</kd>
                </ode>
            </contact>
            <friction>
                <ode>
                <mu>1</mu>
                <mu2>1</mu2>
                <fdir1>0 0 1</fdir1>
                </ode>
            </friction>
            </surface>
        </collision>
        <visual name='left_front_wheel_visual'>
            <pose>0 0 0 0 -0 0</pose>
            <geometry>
            <mesh>
                <scale>1 1 1</scale>
                <uri>/root/dd_ws/install/racecar_description/share/racecar_description/meshes/left_front_wheel.STL</uri>
            </mesh>
            </geometry>
            <material>
            <script>
                <name>Gazebo/Black</name>
                <uri>file://media/materials/scripts/gazebo.material</uri>
            </script>
            </material>
        </visual>
        <gravity>1</gravity>
        <velocity_decay/>
        </link>
        <joint name='right_rear_wheel_joint' type='revolute'>
        <pose relative_to='base_link'>0 -0.1 0.05 1.5708 -0 0</pose>
        <parent>base_link</parent>
        <child>right_rear_wheel</child>
        <axis>
            <xyz>0 0 -1</xyz>
            <limit>
            <lower>-1e+16</lower>
            <upper>1e+16</upper>
            </limit>
            <dynamics>
            <spring_reference>0</spring_reference>
            <spring_stiffness>0</spring_stiffness>
            </dynamics>
        </axis>
        </joint>
        <link name='right_rear_wheel'>
        <pose relative_to='right_rear_wheel_joint'>0 0 0 0 -0 0</pose>
        <inertial>
            <pose>0 0 0.0225 0 -0 0</pose>
            <mass>0.34055</mass>
            <inertia>
            <ixx>0.00026046</ixx>
            <ixy>0</ixy>
            <ixz>0</ixz>
            <iyy>0.00026046</iyy>
            <iyz>0</iyz>
            <izz>0.00041226</izz>
            </inertia>
        </inertial>
        <collision name='right_rear_wheel_collision'>
            <pose>0 0 0.0225 0 -0 0</pose>
            <geometry>
            <cylinder>
                <length>0.045</length>
                <radius>0.05</radius>
            </cylinder>
            </geometry>
            <surface>
            <contact>
                <ode>
                <kp>1e+07</kp>
                <kd>1</kd>
                </ode>
            </contact>
            <friction>
                <ode>
                <mu>1</mu>
                <mu2>1</mu2>
                <fdir1>1 0 0</fdir1>
                </ode>
            </friction>
            </surface>
        </collision>
        <visual name='right_rear_wheel_visual'>
            <pose>0 0 0 0 -0 0</pose>
            <geometry>
            <mesh>
                <scale>1 1 1</scale>
                <uri>/root/dd_ws/install/racecar_description/share/racecar_description/meshes/right_rear_wheel.STL</uri>
            </mesh>
            </geometry>
            <material>
            <script>
                <name>Gazebo/Black</name>
                <uri>file://media/materials/scripts/gazebo.material</uri>
            </script>
            </material>
        </visual>
        <gravity>1</gravity>
        <velocity_decay/>
        </link>
        <joint name='right_steering_hinge_joint' type='revolute'>
        <pose relative_to='base_link'>0.325 -0.1 0.05 3.14159 1.57079 3.14159</pose>
        <parent>base_link</parent>
        <child>right_steering_hinge</child>
        <axis>
            <xyz>-1 0 0</xyz>
            <limit>
            <lower>-1e+16</lower>
            <upper>1e+16</upper>
            </limit>
            <dynamics>
            <spring_reference>0</spring_reference>
            <spring_stiffness>0</spring_stiffness>
            </dynamics>
        </axis>
        </joint>
        <link name='right_steering_hinge'>
        <pose relative_to='right_steering_hinge_joint'>0 0 0 0 -0 0</pose>
        <inertial>
            <pose>0 0 0 0 -0 0</pose>
            <mass>0.1</mass>
            <inertia>
            <ixx>4e-06</ixx>
            <ixy>0</ixy>
            <ixz>0</ixz>
            <iyy>4e-06</iyy>
            <iyz>0</iyz>
            <izz>4e-06</izz>
            </inertia>
        </inertial>
        <visual name='right_steering_hinge_visual'>
            <pose>0 0 0 0 -0 0</pose>
            <geometry>
            <mesh>
                <scale>1 1 1</scale>
                <uri>/root/dd_ws/install/racecar_description/share/racecar_description/meshes/right_steering_hinge.STL</uri>
            </mesh>
            </geometry>
        </visual>
        </link>
        <joint name='right_front_wheel_joint' type='revolute'>
        <pose relative_to='right_steering_hinge'>0 0 0 1.5708 -0 0</pose>
        <parent>right_steering_hinge</parent>
        <child>right_front_wheel</child>
        <axis>
            <xyz>0 0 -1</xyz>
            <limit>
            <lower>-1e+16</lower>
            <upper>1e+16</upper>
            </limit>
            <dynamics>
            <spring_reference>0</spring_reference>
            <spring_stiffness>0</spring_stiffness>
            </dynamics>
        </axis>
        </joint>
        <link name='right_front_wheel'>
        <pose relative_to='right_front_wheel_joint'>0 0 0 0 -0 0</pose>
        <inertial>
            <pose>0 0 0.0225 0 -0 0</pose>
            <mass>0.34055</mass>
            <inertia>
            <ixx>0.00026046</ixx>
            <ixy>0</ixy>
            <ixz>0</ixz>
            <iyy>0.00026046</iyy>
            <iyz>0</iyz>
            <izz>0.00041226</izz>
            </inertia>
        </inertial>
        <collision name='right_front_wheel_collision'>
            <pose>0 0 0.0225 0 -0 0</pose>
            <geometry>
            <cylinder>
                <length>0.045</length>
                <radius>0.05</radius>
            </cylinder>
            </geometry>
            <surface>
            <contact>
                <ode>
                <kp>1e+07</kp>
                <kd>1</kd>
                </ode>
            </contact>
            <friction>
                <ode>
                <mu>1</mu>
                <mu2>1</mu2>
                <fdir1>0 0 1</fdir1>
                </ode>
            </friction>
            </surface>
        </collision>
        <visual name='right_front_wheel_visual'>
            <pose>0 0 0 0 -0 0</pose>
            <geometry>
            <mesh>
                <scale>1 1 1</scale>
                <uri>/root/dd_ws/install/racecar_description/share/racecar_description/meshes/right_front_wheel.STL</uri>
            </mesh>
            </geometry>
            <material>
            <script>
                <name>Gazebo/Black</name>
                <uri>file://media/materials/scripts/gazebo.material</uri>
            </script>
            </material>
        </visual>
        <gravity>1</gravity>
        <velocity_decay/>
        </link>
        <static>0</static>

        <plugin name='ackermann_drive' filename='libgazebo_ros_ackermann_drive.so'>

            <ros>
                <namespace>racecar</namespace>
                <remapping>cmd_vel:=cmd_demo</remapping>
                <remapping>odom:=odom_demo</remapping>
                <remapping>distance:=distance_demo</remapping>
            </ros>

            <update_rate>100.0</update_rate>

            <!-- wheels -->
            <front_left_joint>left_front_wheel_joint</front_left_joint>
            <front_right_joint>right_front_wheel_joint</front_right_joint>
            <rear_left_joint>left_rear_wheel_joint</rear_left_joint>
            <rear_right_joint>right_rear_wheel_joint</rear_right_joint>
            <left_steering_joint>right_steering_hinge_joint</left_steering_joint>
            <right_steering_joint>left_steering_hinge_joint</right_steering_joint>
            <!--steering_wheel_joint>steering_joint</steering_wheel_joint-->

            <!-- Max absolute steer angle for tyre in radians-->
            <!-- Any cmd_vel angular z greater than this would be capped -->
            <max_steer>0.6458</max_steer>

            <!-- Max absolute steering angle of steering wheel -->
            <max_steering_angle>7.85</max_steering_angle>

            <!-- Max absolute linear speed in m/s -->
            <max_speed>10</max_speed>

            <!-- PID tuning -->
            <left_steering_pid_gain>1500 0 1</left_steering_pid_gain>
            <left_steering_i_range>0 0</left_steering_i_range>
            <right_steering_pid_gain>1500 0 1</right_steering_pid_gain>
            <right_steering_i_range>0 0</right_steering_i_range>
            <linear_velocity_pid_gain>1000 0 1</linear_velocity_pid_gain>
            <linear_velocity_i_range>0 0</linear_velocity_i_range>

            <!-- output -->
            <publish_odom>true</publish_odom>
            <publish_odom_tf>true</publish_odom_tf>
            <publish_wheel_tf>true</publish_wheel_tf>
            <publish_distance>true</publish_distance>

            <odometry_frame>odom_demo</odometry_frame>
            <robot_base_frame>chassis</robot_base_frame>

        </plugin>

    </model>
  </world>
</sdf>